Workbook

Sheet MASTER_DATA
A1: Tanggal | B1: Keterangan | C1: Debit | D1: Kredit | E1: Kategori | F1: Sub Kategori | G1: Bulan | H1: Tahun
A2: 01/12 | B2: SALDO | C2: 0 | D2: 18829574 | E2: =IFERROR(LOOKUP(2^15,SEARCH(RULE_KATEGORI!$A$2:$A$100,B2),RULE_KATEGORI!$B$2:$B$100),"OPERASIONAL") | G2: 12 | H2: 2025
A3: 01/12 | B3: BI-FAST CR BIF TRANSFER DR | C3: 600000000 | D3: 618829574 | E3: =IFERROR(LOOKUP(2^15,SEARCH(RULE_KATEGORI!$A$2:$A$100,B3),RULE_KATEGORI!$B$2:$B$100),"OPERASIONAL") | G3: 12 | H3: 2025
A4: 01/12 | B4: BYR VIA E-BANKING 01/12 WSID9527100 | C4: 10300000 | D4: 0 | E4: =IFERROR(LOOKUP(2^15,SEARCH(RULE_KATEGORI!$A$2:$A$100,B4),RULE_KATEGORI!$B$2:$B$100),"OPERASIONAL") | G4: 12 | H4: 2025
A5: 01/12 | B5: TRSF E-BANKING DB 0112/FTSCY/WS95271 | C5: 470000000 | D5: 0 | E5: =IFERROR(LOOKUP(2^15,SEARCH(RULE_KATEGORI!$A$2:$A$100,B5),RULE_KATEGORI!$B$2:$B$100),"OPERASIONAL") | G5: 12 | H5: 2025
A6: 01/12 | B6: TRSF E-BANKING DB 0112/FTFVA/WS95271 | C6: 20000000 | D6: 0 | E6: =IFERROR(LOOKUP(2^15,SEARCH(RULE_KATEGORI!$A$2:$A$100,B6),RULE_KATEGORI!$B$2:$B$100),"OPERASIONAL") | G6: 12 | H6: 2025
A7: 01/12 | B7: TRANSAKSI DEBIT TGL: 01/12 | C7: 35000000 | D7: 0 | E7: =IFERROR(LOOKUP(2^15,SEARCH(RULE_KATEGORI!$A$2:$A$100,B7),RULE_KATEGORI!$B$2:$B$100),"OPERASIONAL") | G7: 12 | H7: 2025
A8: 01/12 | B8: TRSF E-BANKING DB 0112/FTSCY/WS95271 | C8: 30000000 | D8: 0 | E8: =IFERROR(LOOKUP(2^15,SEARCH(RULE_KATEGORI!$A$2:$A$100,B8),RULE_KATEGORI!$B$2:$B$100),"OPERASIONAL") | G8: 12 | H8: 2025
A9: 01/12 | B9: TRSF E-BANKING DB 0112/FTSCY/WS95271 300,000.00 | C9: 0 | D9: 23529574 | E9: =IFERROR(LOOKUP(2^15,SEARCH(RULE_KATEGORI!$A$2:$A$100,B9),RULE_KATEGORI!$B$2:$B$100),"OPERASIONAL") | G9: 12 | H9: 2025
A10: 02/12 | B10: BI-FAST CR BIF TRANSFER | C10: 0 | D10: 15000000 | E10: =IFERROR(LOOKUP(2^15,SEARCH(RULE_KATEGORI!$A$2:$A$100,B10),RULE_KATEGORI!$B$2:$B$100),"OPERASIONAL") | G10: 12 | H10: 2025
A11: 02/12 | B11: BI-FAST CR BIF TRANSFER | C11: 0 | D11: 500000000 | E11: =IFERROR(LOOKUP(2^15,SEARCH(RULE_KATEGORI!$A$2:$A$100,B11),RULE_KATEGORI!$B$2:$B$100),"OPERASIONAL") | G11: 12 | H11: 2025
A12: 02/12 | B12: TRSF E-BANKING DB 0212/FTFVA/WS95271 27,000.00 | C12: 0 | D12: 535829574 | E12: =IFERROR(LOOKUP(2^15,SEARCH(RULE_KATEGORI!$A$2:$A$100,B12),RULE_KATEGORI!$B$2:$B$100),"OPERASIONAL") | G12: 12 | H12: 2025
A13: 71231/XL | B13: PULSA | C13: 0 | D13: 2 | E13: =IFERROR(LOOKUP(2^15,SEARCH(RULE_KATEGORI!$A$2:$A$100,B13),RULE_KATEGORI!$B$2:$B$100),"OPERASIONAL") | G13: 12 | H13: 2025
A14: 02/12 | B14: TRANSAKSI DEBIT TGL: 02/12 50,000.00 | C14: 0 | D14: 530829574 | E14: =IFERROR(LOOKUP(2^15,SEARCH(RULE_KATEGORI!$A$2:$A$100,B14),RULE_KATEGORI!$B$2:$B$100),"OPERASIONAL") | G14: 12 | H14: 2025
A15: 02/12 | B15: TRANSAKSI DEBIT TGL: 02/12 | C15: 3350000 | D15: 0 | E15: =IFERROR(LOOKUP(2^15,SEARCH(RULE_KATEGORI!$A$2:$A$100,B15),RULE_KATEGORI!$B$2:$B$100),"OPERASIONAL") | G15: 12 | H15: 2025
... A26: 06/12 | B26: TRANSAKSI DEBIT TGL: 06/12 10,000.00 | C26: 0 | D26: 5349574 | E26: =IFERROR(LOOKUP(2^15,SEARCH(RULE_KATEGORI!$A$2:$A$100,B26),RULE_KATEGORI!$B$2:$B$100),"OPERASIONAL") | G26: 12 | H26: 2025
A27: 07/12 | B27: SWITCHING CR DR | C27: 451 | D27: 50000000 | E27: =IFERROR(LOOKUP(2^15,SEARCH(RULE_KATEGORI!$A$2:$A$100,B27),RULE_KATEGORI!$B$2:$B$100),"OPERASIONAL") | G27: 12 | H27: 2025
A28: 07/12 | B28: BI-FAST DB BIF TRANSFER KE | C28: 10000000 | D28: 0 | E28: =IFERROR(LOOKUP(2^15,SEARCH(RULE_KATEGORI!$A$2:$A$100,B28),RULE_KATEGORI!$B$2:$B$100),"OPERASIONAL") | G28: 12 | H28: 2025
A29: 07/12 | B29: BI-FAST DB BIF BIAYA TXN KE | C29: 250000 | D29: 0 | E29: =IFERROR(LOOKUP(2^15,SEARCH(RULE_KATEGORI!$A$2:$A$100,B29),RULE_KATEGORI!$B$2:$B$100),"OPERASIONAL") | G29: 12 | H29: 2025
A30: 07/12 | B30: TRSF E-BANKING DB 0712/FTFVA/WS95271 51,000.00 | C30: 0 | D30: 39999574 | E30: =IFERROR(LOOKUP(2^15,SEARCH(RULE_KATEGORI!$A$2:$A$100,B30),RULE_KATEGORI!$B$2:$B$100),"OPERASIONAL") | G30: 12 | H30: 2025
A31: 08/12 | B31: BI-FAST DB BIF TRANSFER KE | C31: 10000000 | D31: 0 | E31: =IFERROR(LOOKUP(2^15,SEARCH(RULE_KATEGORI!$A$2:$A$100,B31),RULE_KATEGORI!$B$2:$B$100),"OPERASIONAL") | G31: 12 | H31: 2025
A32: 08/12 | B32: BI-FAST DB BIF BIAYA TXN KE | C32: 250000 | D32: 0 | E32: =IFERROR(LOOKUP(2^15,SEARCH(RULE_KATEGORI!$A$2:$A$100,B32),RULE_KATEGORI!$B$2:$B$100),"OPERASIONAL") | G32: 12 | H32: 2025
A33: 08/12 | B33: TRANSAKSI DEBIT TGL: 08/12 45,000.00 | C33: 0 | D33: 25249574 | E33: =IFERROR(LOOKUP(2^15,SEARCH(RULE_KATEGORI!$A$2:$A$100,B33),RULE_KATEGORI!$B$2:$B$100),"OPERASIONAL") | G33: 12 | H33: 2025
A34: 09/12 | B34: TRSF E-BANKING DB 0812/FTFVA/WS95271 55,000.00 | C34: 0 | D34: 19749574 | E34: =IFERROR(LOOKUP(2^15,SEARCH(RULE_KATEGORI!$A$2:$A$100,B34),RULE_KATEGORI!$B$2:$B$100),"OPERASIONAL") | G34: 12 | H34: 2025
A35: 09/12 | B35: TRSF E-BANKING DB 0912/FTSCY/WS95271 100,000.00 | C35: 0 | D35: 9749574 | E35: =IFERROR(LOOKUP(2^15,SEARCH(RULE_KATEGORI!$A$2:$A$100,B35),RULE_KATEGORI!$B$2:$B$100),"OPERASIONAL") | G35: 12 | H35: 2025
A36: 09/12 | B36: TRSF E-BANKING CR | C36: 0 | D36: 5000000 | E36: =IFERROR(LOOKUP(2^15,SEARCH(RULE_KATEGORI!$A$2:$A$100,B36),RULE_KATEGORI!$B$2:$B$100),"OPERASIONAL") | G36: 12 | H36: 2025
A37: 09/12 | B37: TRANSAKSI DEBIT TGL: 09/12 | C37: 1930000 | D37: 0 | E37: =IFERROR(LOOKUP(2^15,SEARCH(RULE_KATEGORI!$A$2:$A$100,B37),RULE_KATEGORI!$B$2:$B$100),"OPERASIONAL") | G37: 12 | H37: 2025
A38: 09/12 | B38: BYR VIA E-BANKING 09/12 WSID9527100 | C38: 5300000 | D38: 0 | E38: =IFERROR(LOOKUP(2^15,SEARCH(RULE_KATEGORI!$A$2:$A$100,B38),RULE_KATEGORI!$B$2:$B$100),"OPERASIONAL") | G38: 12 | H38: 2025
A39: 09/12 | B39: SWITCHING CR DR | C39: 451 | D39: 50000000 | E39: =IFERROR(LOOKUP(2^15,SEARCH(RULE_KATEGORI!$A$2:$A$100,B39),RULE_KATEGORI!$B$2:$B$100),"OPERASIONAL") | G39: 12 | H39: 2025
A40: 09/12 | B40: TRANSAKSI DEBIT TGL: 09/12 | C40: 1380000 | D40: 0 | E40: =IFERROR(LOOKUP(2^15,SEARCH(RULE_KATEGORI!$A$2:$A$100,B40),RULE_KATEGORI!$B$2:$B$100),"OPERASIONAL") | G40: 12 | H40: 2025
A41: 09/12 | B41: TRANSAKSI DEBIT TGL: 09/12 264,000.00 | C41: 0 | D41: 29739574 | E41: =IFERROR(LOOKUP(2^15,SEARCH(RULE_KATEGORI!$A$2:$A$100,B41),RULE_KATEGORI!$B$2:$B$100),"OPERASIONAL") | G41: 12 | H41: 2025
A42: 10/12 | B42: BI-FAST CR BIF TRANSFER | C42: 0 | D42: 1960000000 | E42: =IFERROR(LOOKUP(2^15,SEARCH(RULE_KATEGORI!$A$2:$A$100,B42),RULE_KATEGORI!$B$2:$B$100),"OPERASIONAL") | G42: 12 | H42: 2025
A43: 10/12 | B43: TRSF E-BANKING DB 1012/FTFVA/WS95271 | C43: 25174500 | D43: 0 | E43: =IFERROR(LOOKUP(2^15,SEARCH(RULE_KATEGORI!$A$2:$A$100,B43),RULE_KATEGORI!$B$2:$B$100),"OPERASIONAL") | G43: 12 | H43: 2025
A44: 10/12 | B44: BYR VIA E-BANKING 10/12 WSID9527100 | C44: 10300000 | D44: 0 | E44: =IFERROR(LOOKUP(2^15,SEARCH(RULE_KATEGORI!$A$2:$A$100,B44),RULE_KATEGORI!$B$2:$B$100),"OPERASIONAL") | G44: 12 | H44: 2025
A45: 10/12 | B45: TRSF E-BANKING DB 1012/FTFVA/WS95271 1,276,500.00 | C45: 0 | D45: 1826615074 | E45: =IFERROR(LOOKUP(2^15,SEARCH(RULE_KATEGORI!$A$2:$A$100,B45),RULE_KATEGORI!$B$2:$B$100),"OPERASIONAL") | G45: 12 | H45: 2025
A46: 10/12 | B46: TRSF E-BANKING DB 1012/FTSCY/WS95271 1,267,000.00 | C46: 0 | D46: 1699915074 | E46: =IFERROR(LOOKUP(2^15,SEARCH(RULE_KATEGORI!$A$2:$A$100,B46),RULE_KATEGORI!$B$2:$B$100),"OPERASIONAL") | G46: 12 | H46: 2025
A47: 10/12 | B47: TRSF E-BANKING DB 1012/FTSCY/WS95271 | C47: 10000000 | D47: 0 | E47: =IFERROR(LOOKUP(2^15,SEARCH(RULE_KATEGORI!$A$2:$A$100,B47),RULE_KATEGORI!$B$2:$B$100),"OPERASIONAL") | G47: 12 | H47: 2025
A48: 10/12 | B48: SWITCHING CR DR | C48: 008 | D48: 40000000 | E48: =IFERROR(LOOKUP(2^15,SEARCH(RULE_KATEGORI!$A$2:$A$100,B48),RULE_KATEGORI!$B$2:$B$100),"OPERASIONAL") | G48: 12 | H48: 2025
A49: 10/12 | B49: TRSF E-BANKING DB 1012/FTSCY/WS95271 | C49: 50000000 | D49: 0 | E49: =IFERROR(LOOKUP(2^15,SEARCH(RULE_KATEGORI!$A$2:$A$100,B49),RULE_KATEGORI!$B$2:$B$100),"OPERASIONAL") | G49: 12 | H49: 2025
A50: 10/12 | B50: BI-FAST DB BIF TRANSFER KE | C50: 50000000 | D50: 0 | E50: =IFERROR(LOOKUP(2^15,SEARCH(RULE_KATEGORI!$A$2:$A$100,B50),RULE_KATEGORI!$B$2:$B$100),"OPERASIONAL") | G50: 12 | H50: 2025
...

Sheet SUMMARY
A1: SUMMARY PER KATEGORI
A2: Kategori | B2: Total (Rp)
A3: PEMASUKAN | B3: =SUMIF(MASTER_DATA!E:E,"PEMASUKAN*",MASTER_DATA!C:C)+SUMIF(MASTER_DATA!E:E,"PEMASUKAN*",MASTER_DATA!D:D)
A4: GAJI | B4: =SUMIF(MASTER_DATA!E:E,"GAJI*",MASTER_DATA!C:C)+SUMIF(MASTER_DATA!E:E,"GAJI*",MASTER_DATA!D:D)
A5: BELANJA ONLINE | B5: =SUMIF(MASTER_DATA!E:E,"BELANJA ONLINE*",MASTER_DATA!C:C)+SUMIF(MASTER_DATA!E:E,"BELANJA ONLINE*",MASTER_DATA!D:D)
A6: OPERASIONAL | B6: =SUMIF(MASTER_DATA!E:E,"OPERASIONAL*",MASTER_DATA!C:C)+SUMIF(MASTER_DATA!E:E,"OPERASIONAL*",MASTER_DATA!D:D)
A7: LISTRIK | B7: =SUMIF(MASTER_DATA!E:E,"LISTRIK*",MASTER_DATA!C:C)+SUMIF(MASTER_DATA!E:E,"LISTRIK*",MASTER_DATA!D:D)
A8: PRIVE | B8: =SUMIF(MASTER_DATA!E:E,"PRIVE*",MASTER_DATA!C:C)+SUMIF(MASTER_DATA!E:E,"PRIVE*",MASTER_DATA!D:D)

Sheet LABA_RUGI
A1: LAPORAN LABA RUGI
A2: Pendapatan | B2: =SUMIF(MASTER_DATA!E:E,"PEMASUKAN*",MASTER_DATA!D:D)
A3: Beban | B3: =SUM(MASTER_DATA!C:C)
A4: Laba Bersih | B4: =B2-B3

Sheet NERACA
A1: NERACA
A2: ASET
A3: Kas/Bank | B3: =SUMMARY!B2
A5: MODAL
A6: Modal Awal | B6: 0
A7: Laba Ditahan | B7: =SUMMARY!B4
A8: Prive | B8: =SUMIF(MASTER_DATA!E:E,"PRIVE",MASTER_DATA!C:C)

Sheet GRAFIK
A1: DASHBOARD GRAFIK
A2: Keterangan | B2: Nilai
A3: Pemasukan | B3: =SUMMARY!B2
A4: Pengeluaran | B4: =SUMMARY!B3
A5: Laba | B5: =SUMMARY!B4
A7: Kategori | B7: Total
A8: PEMASUKAN | B8: =SUMIF(MASTER_DATA!E:E,"PEMASUKAN",MASTER_DATA!C:C)+SUMIF(MASTER_DATA!E:E,"PEMASUKAN",MASTER_DATA!D:D)
A9: GAJI | B9: =SUMIF(MASTER_DATA!E:E,"GAJI",MASTER_DATA!C:C)+SUMIF(MASTER_DATA!E:E,"GAJI",MASTER_DATA!D:D)
A10: BELANJA ONLINE | B10: =SUMIF(MASTER_DATA!E:E,"BELANJA ONLINE",MASTER_DATA!C:C)+SUMIF(MASTER_DATA!E:E,"BELANJA ONLINE",MASTER_DATA!D:D)
A11: OPERASIONAL | B11: =SUMIF(MASTER_DATA!E:E,"OPERASIONAL",MASTER_DATA!C:C)+SUMIF(MASTER_DATA!E:E,"OPERASIONAL",MASTER_DATA!D:D)
A12: LISTRIK | B12: =SUMIF(MASTER_DATA!E:E,"LISTRIK",MASTER_DATA!C:C)+SUMIF(MASTER_DATA!E:E,"LISTRIK",MASTER_DATA!D:D)
A13: PRIVE | B13: =SUMIF(MASTER_DATA!E:E,"PRIVE",MASTER_DATA!C:C)+SUMIF(MASTER_DATA!E:E,"PRIVE",MASTER_DATA!D:D)

Sheet RULE_KATEGORI
A1: Keyword BCA | B1: Kategori
A2: TRF DARI | B2: PEMASUKAN
A3: SETOR | B3: PEMASUKAN
A4: GAJI | B4: GAJI
A5: UPAH | B5: GAJI
A6: SHOPEE | B6: BELANJA ONLINE
A7: TOKOPEDIA | B7: BELANJA ONLINE
A8: GOJEK | B8: BELANJA ONLINE
A9: GRAB | B9: BELANJA ONLINE
A10: PLN | B10: LISTRIK
A11: TOKEN | B11: LISTRIK
A12: BBM | B12: OPERASIONAL
... A14: PRIVE | B14: PRIVE

Sheet TEMPLATE_BULANAN
A1: Bulan | B1: Total Pemasukan | C1: Total Pengeluaran | D1: Laba Bersih
A2: Jan | B2: =SUMIFS(MASTER_DATA!D:D,MASTER_DATA!F:F,"01") | C2: =SUMIFS(MASTER_DATA!C:C,MASTER_DATA!F:F,"01") | D2: =B2-C2
A3: Feb | B3: =SUMIFS(MASTER_DATA!D:D,MASTER_DATA!F:F,"02") | C3: =SUMIFS(MASTER_DATA!C:C,MASTER_DATA!F:F,"02") | D3: =B3-C3
A4: Mar | B4: =SUMIFS(MASTER_DATA!D:D,MASTER_DATA!F:F,"03") | C4: =SUMIFS(MASTER_DATA!C:C,MASTER_DATA!F:F,"03") | D4: =B4-C4
A5: Apr | B5: =SUMIFS(MASTER_DATA!D:D,MASTER_DATA!F:F,"04") | C5: =SUMIFS(MASTER_DATA!C:C,MASTER_DATA!F:F,"04") | D5: =B5-C5
A6: Mei | B6: =SUMIFS(MASTER_DATA!D:D,MASTER_DATA!F:F,"05") | C6: =SUMIFS(MASTER_DATA!C:C,MASTER_DATA!F:F,"05") | D6: =B6-C6
A7: Jun | B7: =SUMIFS(MASTER_DATA!D:D,MASTER_DATA!F:F,"06") | C7: =SUMIFS(MASTER_DATA!C:C,MASTER_DATA!F:F,"06") | D7: =B7-C7
A8: Jul | B8: =SUMIFS(MASTER_DATA!D:D,MASTER_DATA!F:F,"07") | C8: =SUMIFS(MASTER_DATA!C:C,MASTER_DATA!F:F,"07") | D8: =B8-C8
A9: Agu | B9: =SUMIFS(MASTER_DATA!D:D,MASTER_DATA!F:F,"08") | C9: =SUMIFS(MASTER_DATA!C:C,MASTER_DATA!F:F,"08") | D9: =B9-C9
A10: Sep | B10: =SUMIFS(MASTER_DATA!D:D,MASTER_DATA!F:F,"09") | C10: =SUMIFS(MASTER_DATA!C:C,MASTER_DATA!F:F,"09") | D10: =B10-C10
A11: Okt | B11: =SUMIFS(MASTER_DATA!D:D,MASTER_DATA!F:F,"10") | C11: =SUMIFS(MASTER_DATA!C:C,MASTER_DATA!F:F,"10") | D11: =B11-C11
A12: Nov | B12: =SUMIFS(MASTER_DATA!D:D,MASTER_DATA!F:F,"11") | C12: =SUMIFS(MASTER_DATA!C:C,MASTER_DATA!F:F,"11") | D12: =B12-C12
A13: Des | B13: =SUMIFS(MASTER_DATA!D:D,MASTER_DATA!F:F,"12") | C13: =SUMIFS(MASTER_DATA!C:C,MASTER_DATA!F:F,"12") | D13: =B13-C13
